Workbook

Sheet Start Here
B1: Market Research Workbook
B2: Your own research, your own numbers. Every calculation is a plain formula you can click on and check.
B4: How the colors work
B5: Yellow cell, blue text | C5: You type it (from a source you checked).
B6: Gray cell, black text | C6: Calculated. Don't type here; click it to see the formula.
B7: Gray cell, green text | C7: Pulled in from another tab.
B8: Light blue cell | C8: Filled in by OfferDesk from public data (Research pack). Spot-check a few against the source.
B9: Italic first row | C9: An EXAMPLE row ("Sampleville, OH") so you can see the format. Delete it once you have your own rows.
B11: The plan (about 4–5 weeks for ALL your metros, done side by side)
B12: 1. Metros | C12: Week 1: write your 3–5 candidate metros in the Metros tab (column A), same name everywhere. Do steps 2–4 for all of them, then cut to your best 2.
B13: 2. ZIPs | C13: For each metro, add 5–8 ZIPs. Faster: star the metros in OfferDesk → Markets → Research pack, and it fills this tab (light blue). Then spot-check 3 ZIPs per metro with the Redfin link.
B14: 3. Listing Watch | C14: Save 20–30 listings in your price range per metro. Update status and price once a week.
B15: 4. Past Flips | C15: Find houses that sold cheap, then resold renovated within 12 months. OfferDesk lists likely ones in Flip Candidates; you check each one's sale history and type the earlier sale.
B16: 5. Calls | C16: Weeks 2–3, your 2 finalists only: call 10 locals each (3 agents, 2 property managers, 2 contractors, 1 hard-money lender, 1 title company). Same questions every time.
B17: 6. Metros | C17: Everything rolls up here. Set your own weights; the score ranks your metros against each other.
B18: 7. Paper Flips | C18: Run your numbers on 10 real listings in the Deal Check tab, log them here, then check what they really sold for.
B19: 8. Ready check | C19: Bottom of the Metros tab. Don't buy in a metro until every box says Yes.
B20: Weekly | C20: In OfferDesk, drop your new Redfin downloads, then "Update my workbook": it refreshes the light-blue rows and adds new listings. Rows you edit yourself are never overwritten once you change their Source/Notes cell.
B22: Where to get each number
B23: Number | C23: Where (free) | D23: How
B24: Median sale price, homes sold, days on market, sale-to-list, % sold above list, price change, active listings | C24: Redfin ZIP housing market page https://www.redfin.com/zipcode/44102/housing-market | D24: Swap in your ZIP (the ZIPs tab builds this link for you). Use the "last 3 months" numbers and stay consistent.
B25: Same numbers, all ZIPs at once | C25: Redfin Data Center https://www.redfin.com/news/data-center/ | D25: Download "ZIP code" market tracker data if you want to check many ZIPs.
B26: Typical rent, 3-bed | C26: HUD Fair Market Rents (by ZIP), or Zillow rentals https://www.huduser.gov/portal/datasets/fmr.html | D26: Use the Small Area FMR for the ZIP. Cross-check with 3–5 real rentals on Zillow, and ask a property manager.
B27: Owner vs. rented single-family homes | C27: Census table B25032 (data.census.gov) https://data.census.gov/table/ACSDT5Y2024.B25032 | D27: Line 3 = owner-occupied "1, detached". Line 14 = renter-occupied "1, detached". The ZIPs tab link opens it for your ZIP; if it doesn't, pick Geography → ZIP Code Tabulation Area and type the ZIP.
B28: Median year built | C28: Census table B25035 https://data.census.gov/table/ACSDT5Y2024.B25035 | D28: One number per ZIP.
B29: Median household income | C29: Census table B19013, or Census Reporter https://censusreporter.org/ | D29: Census Reporter has an easy page per ZIP (the ZIPs tab links it).
B30: County jobs (2-year change) | C30: BLS QCEW (county employment) https://www.bls.gov/cew/ | D30: Compare total employment now vs. the same quarter 2 years ago.
B31: County population since 2020 | C31: Census population estimates https://www.census.gov/programs-surveys/popest.html | D31: County totals. Compare the latest year to 2020.
B32: Past flips | C32: Zillow / Redfin "sale history", county recorder or assessor site | D32: A house that sold, then sold again within 12 months for a lot more, is almost always a flip.
B33: Flip rates for big metros | C33: ATTOM home flipping report (quarterly) https://www.attomdata.com/news/market-trends/flipping/ | D33: Flips as a % of all sales. The US average was 8% in early 2026.
B34: "We buy houses" competition | C34: Google, Facebook groups, the local investor club (REIA) | D34: Search "we buy houses [city]" and count the different companies on the first 3 pages, ads included.
B36: Ask every local the same questions
B37: • What does a renovated 3-bed, 1–2 bath sell for in [ZIP] right now?
B38: • What does a cosmetic rehab cost per square foot here? A full gut?
B39: • What would that house rent for?
B40: • Which areas sell fast, and which ones sit? Where would you not buy?
B41: • How many investors and flippers are buying here? (1 = few, 5 = crowded)
B42: • Who are the active flippers? Which lenders and contractors do they use?
B43: • Title companies: what share of your closings are off-market or wholesale deals?
B44: • Would you work with an out-of-state buyer? What do you need from me?
...

Sheet Metros
A1: Metros
A2: Your candidate metros side by side. Most columns fill themselves from the other tabs. Set your own weights in row 6; the score compares your metros to each other.
X5: Your weights (row 6, should add to 100) → | AH5: =SUM(X6:AG6) -> 100 | AI5: total
B6: From your ZIPs tab | I6: From Past Flips + Flip Candidates | L6: From Listing Watch | O6: From Calls | S6: Competition | T6: You type | W6: Result | X6: 15 | Y6: 10 | Z6: 10 | AA6: 5 | AB6: 15 | AC6: 15 | AD6: 10 | AE6: 8 | AF6: 7 | AG6: 5
A7: Metro (exact same name in every tab) | B7: ZIPs researched | C7: Typical median price ($) | D7: Sales, last 3 mo (your ZIPs) | E7: Avg days on market | F7: Avg price change, 1 yr | G7: Avg rent yield | H7: Avg share of houses rented out | I7: Flips found, 12 mo | J7: Flips as % of sales (est.) | K7: Avg est. flip profit (% of resale) | L7: Listings watched | M7: Avg days to pending | N7: Share with a price cut | O7: Calls logged | P7: Avg competition from calls (1–5) | Q7: Avg renovated 3-bed price, calls ($) | R7: Avg cosmetic rehab $/sqft, calls | S7: "We buy houses" companies (Competition tab) | T7: County jobs, 2 yrs | U7: County population since 2020 | V7: Your rating after visiting (1–5) | W7: YOUR SCORE (0–100) | X7: Points: Deal volume | Y7: Points: Sells fast | Z7: Points: Price trend | AA7: Points: Rent yield | AB7: Points: Fewer flippers | AC7: Points: Calls say less crowded | AD7: Points: Fewer "we buy houses" | AE7: Points: Job growth | AF7: Points: Population growth | AG7: Points: Your rating
A8: Sampleville, OH | B8: =IF($A8="","",COUNTIF(ZIPs!$A$8:$A$107,$A8)) -> 1 | C8: =IF($A8="","",IF($B8=0,"",IFERROR(AVERAGEIFS(ZIPs!$D$8:$D$107,ZIPs!$A$8:$A$107,$A8),""))) -> 185000 | D8: =IF($A8="","",IF($B8=0,"",SUMIFS(ZIPs!$E$8:$E$107,ZIPs!$A$8:$A$107,$A8))) -> 42 | E8: =IF($A8="","",IF($B8=0,"",IFERROR(AVERAGEIFS(ZIPs!$G$8:$G$107,ZIPs!$A$8:$A$107,$A8),""))) -> 34 | F8: =IF($A8="","",IF($B8=0,"",IFERROR(AVERAGEIFS(ZIPs!$J$8:$J$107,ZIPs!$A$8:$A$107,$A8),""))) -> 0.041 | G8: =IF($A8="","",IF($B8=0,"",IFERROR(AVERAGEIFS(ZIPs!$S$8:$S$107,ZIPs!$A$8:$A$107,$A8),""))) -> 0.094054054 | H8: =IF($A8="","",IF($B8=0,"",IFERROR(AVERAGEIFS(ZIPs!$T$8:$T$107,ZIPs!$A$8:$A$107,$A8),""))) -> 0.1774744 | I8: =IF($A8="","",COUNTIF('Past Flips'!$A$8:$A$307,$A8)+COUNTIFS('Flip Candidates'!$A$8:$A$207,$A8,'Flip Candidates'!$O$8:$O$207,"Likely flip")) -> 2 | J8: =IF(OR($A8="",D8="",D8=0),"",I8/(D8*4)) -> 0.011904762 | K8: =IF($A8="","",IFERROR((SUMIFS('Past Flips'!$T$8:$T$307,'Past Flips'!$A$8:$A$307,$A8)+SUMIFS('Flip Candidates'!$R$8:$R$207,'Flip Candidates'!$A$8:$A$207,$A8,'Flip Candidates'!$O$8:$O$207,"Likely flip"))/(COUNTIFS('Past Flips'!$A$8:$A$307,$A8,'Past Flips'!$T$8:$T$307,"<>")+COUNTIFS('Flip Candidates'!$A$8:$A$207,$A8,'Flip Candidates'!$O$8:$O$207,"Likely flip")),"")) -> 0.17705832 | L8: =IF($A8="","",COUNTIF('Listing Watch'!$A$8:$A$307,$A8)) -> 1 | M8: =IF($A8="","",IFERROR(AVERAGEIFS('Listing Watch'!$S$8:$S$307,'Listing Watch'!$A$8:$A$307,$A8),"")) -> 31 | N8: =IF(OR($A8="",L8=0),"",COUNTIFS('Listing Watch'!$A$8:$A$307,$A8,'Listing Watch'!$R$8:$R$307,">0")/L8) -> 1 | O8: =IF($A8="","",COUNTIF(Calls!$A$8:$A$307,$A8)) -> 1 | P8: =IF($A8="","",IFERROR(AVERAGEIFS(Calls!$K$8:$K$307,Calls!$A$8:$A$307,$A8),"")) -> 3 | Q8: =IF($A8="","",IFERROR(AVERAGEIFS(Calls!$G$8:$G$307,Calls!$A$8:$A$307,$A8),"")) -> 215000 | R8: =IF($A8="","",IFERROR(AVERAGEIFS(Calls!$H$8:$H$307,Calls!$A$8:$A$307,$A8),"")) -> 25 | S8: =IF($A8="","",IF(COUNTIF(Competition!$A$8:$A$207,$A8)=0,"",COUNTIF(Competition!$A$8:$A$207,$A8))) -> 1 | T8: 0.018 | U8: 0.024 | W8: =IF($A8="","",IFERROR(ROUND(100*SUMPRODUCT($X$6:$AG$6,X8:AG8)/SUMPRODUCT($X$6:$AG$6,--(X8:AG8<>"")),0),"")) -> 100 | X8: =IF(OR($A8="",D8=""),"",IF(COUNT(D$8:D$13)<2,1,(COUNT(D$8:D$13)-RANK(D8,D$8:D$13,0))/(COUNT(D$8:D$13)-1))) -> 1 | Y8: =IF(OR($A8="",E8=""),"",IF(COUNT(E$8:E$13)<2,1,(COUNT(E$8:E$13)-RANK(E8,E$8:E$13,1))/(COUNT(E$8:E$13)-1))) -> 1 | Z8: =IF(OR($A8="",F8=""),"",IF(COUNT(F$8:F$13)<2,1,(COUNT(F$8:F$13)-RANK(F8,F$8:F$13,0))/(COUNT(F$8:F$13)-1))) -> 1 | AA8: =IF(OR($A8="",G8=""),"",IF(COUNT(G$8:G$13)<2,1,(COUNT(G$8:G$13)-RANK(G8,G$8:G$13,0))/(COUNT(G$8:G$13)-1))) -> 1 | AB8: =IF(OR($A8="",J8=""),"",IF(COUNT(J$8:J$13)<2,1,(COUNT(J$8:J$13)-RANK(J8,J$8:J$13,1))/(COUNT(J$8:J$13)-1))) -> 1 | AC8: =IF(OR($A8="",P8=""),"",IF(COUNT(P$8:P$13)<2,1,(COUNT(P$8:P$13)-RANK(P8,P$8:P$13,1))/(COUNT(P$8:P$13)-1))) -> 1 | AD8: =IF(OR($A8="",S8=""),"",IF(COUNT(S$8:S$13)<2,1,(COUNT(S$8:S$13)-RANK(S8,S$8:S$13,1))/(COUNT(S$8:S$13)-1))) -> 1 | AE8: =IF(OR($A8="",T8=""),"",IF(COUNT(T$8:T$13)<2,1,(COUNT(T$8:T$13)-RANK(T8,T$8:T$13,0))/(COUNT(T$8:T$13)-1))) -> 1 | AF8: =IF(OR($A8="",U8=""),"",IF(COUNT(U$8:U$13)<2,1,(COUNT(U$8:U$13)-RANK(U8,U$8:U$13,0))/(COUNT(U$8:U$13)-1))) -> 1 | AG8: =IF(OR($A8="",V8=""),"",IF(COUNT(V$8:V$13)<2,1,(COUNT(V$8:V$13)-RANK(V8,V$8:V$13,0))/(COUNT(V$8:V$13)-1)))
B9: =IF($A9="","",COUNTIF(ZIPs!$A$8:$A$107,$A9)) | C9: =IF($A9="","",IF($B9=0,"",IFERROR(AVERAGEIFS(ZIPs!$D$8:$D$107,ZIPs!$A$8:$A$107,$A9),""))) | D9: =IF($A9="","",IF($B9=0,"",SUMIFS(ZIPs!$E$8:$E$107,ZIPs!$A$8:$A$107,$A9))) | E9: =IF($A9="","",IF($B9=0,"",IFERROR(AVERAGEIFS(ZIPs!$G$8:$G$107,ZIPs!$A$8:$A$107,$A9),""))) | F9: =IF($A9="","",IF($B9=0,"",IFERROR(AVERAGEIFS(ZIPs!$J$8:$J$107,ZIPs!$A$8:$A$107,$A9),""))) | G9: =IF($A9="","",IF($B9=0,"",IFERROR(AVERAGEIFS(ZIPs!$S$8:$S$107,ZIPs!$A$8:$A$107,$A9),""))) | H9: =IF($A9="","",IF($B9=0,"",IFERROR(AVERAGEIFS(ZIPs!$T$8:$T$107,ZIPs!$A$8:$A$107,$A9),""))) | I9: =IF($A9="","",COUNTIF('Past Flips'!$A$8:$A$307,$A9)+COUNTIFS('Flip Candidates'!$A$8:$A$207,$A9,'Flip Candidates'!$O$8:$O$207,"Likely flip")) | J9: =IF(OR($A9="",D9="",D9=0),"",I9/(D9*4)) | K9: =IF($A9="","",IFERROR((SUMIFS('Past Flips'!$T$8:$T$307,'Past Flips'!$A$8:$A$307,$A9)+SUMIFS('Flip Candidates'!$R$8:$R$207,'Flip Candidates'!$A$8:$A$207,$A9,'Flip Candidates'!$O$8:$O$207,"Likely flip"))/(COUNTIFS('Past Flips'!$A$8:$A$307,$A9,'Past Flips'!$T$8:$T$307,"<>")+COUNTIFS('Flip Candidates'!$A$8:$A$207,$A9,'Flip Candidates'!$O$8:$O$207,"Likely flip")),"")) | L9: =IF($A9="","",COUNTIF('Listing Watch'!$A$8:$A$307,$A9)) | M9: =IF($A9="","",IFERROR(AVERAGEIFS('Listing Watch'!$S$8:$S$307,'Listing Watch'!$A$8:$A$307,$A9),"")) | N9: =IF(OR($A9="",L9=0),"",COUNTIFS('Listing Watch'!$A$8:$A$307,$A9,'Listing Watch'!$R$8:$R$307,">0")/L9) | O9: =IF($A9="","",COUNTIF(Calls!$A$8:$A$307,$A9)) | P9: =IF($A9="","",IFERROR(AVERAGEIFS(Calls!$K$8:$K$307,Calls!$A$8:$A$307,$A9),"")) | Q9: =IF($A9="","",IFERROR(AVERAGEIFS(Calls!$G$8:$G$307,Calls!$A$8:$A$307,$A9),"")) | R9: =IF($A9="","",IFERROR(AVERAGEIFS(Calls!$H$8:$H$307,Calls!$A$8:$A$307,$A9),"")) | S9: =IF($A9="","",IF(COUNTIF(Competition!$A$8:$A$207,$A9)=0,"",COUNTIF(Competition!$A$8:$A$207,$A9))) | W9: =IF($A9="","",IFERROR(ROUND(100*SUMPRODUCT($X$6:$AG$6,X9:AG9)/SUMPRODUCT($X$6:$AG$6,--(X9:AG9<>"")),0),"")) | X9: =IF(OR($A9="",D9=""),"",IF(COUNT(D$8:D$13)<2,1,(COUNT(D$8:D$13)-RANK(D9,D$8:D$13,0))/(COUNT(D$8:D$13)-1))) | Y9: =IF(OR($A9="",E9=""),"",IF(COUNT(E$8:E$13)<2,1,(COUNT(E$8:E$13)-RANK(E9,E$8:E$13,1))/(COUNT(E$8:E$13)-1))) | Z9: =IF(OR($A9="",F9=""),"",IF(COUNT(F$8:F$13)<2,1,(COUNT(F$8:F$13)-RANK(F9,F$8:F$13,0))/(COUNT(F$8:F$13)-1))) | AA9: =IF(OR($A9="",G9=""),"",IF(COUNT(G$8:G$13)<2,1,(COUNT(G$8:G$13)-RANK(G9,G$8:G$13,0))/(COUNT(G$8:G$13)-1))) | AB9: =IF(OR($A9="",J9=""),"",IF(COUNT(J$8:J$13)<2,1,(COUNT(J$8:J$13)-RANK(J9,J$8:J$13,1))/(COUNT(J$8:J$13)-1))) | AC9: =IF(OR($A9="",P9=""),"",IF(COUNT(P$8:P$13)<2,1,(COUNT(P$8:P$13)-RANK(P9,P$8:P$13,1))/(COUNT(P$8:P$13)-1))) | AD9: =IF(OR($A9="",S9=""),"",IF(COUNT(S$8:S$13)<2,1,(COUNT(S$8:S$13)-RANK(S9,S$8:S$13,1))/(COUNT(S$8:S$13)-1))) | AE9: =IF(OR($A9="",T9=""),"",IF(COUNT(T$8:T$13)<2,1,(COUNT(T$8:T$13)-RANK(T9,T$8:T$13,0))/(COUNT(T$8:T$13)-1))) | AF9: =IF(OR($A9="",U9=""),"",IF(COUNT(U$8:U$13)<2,1,(COUNT(U$8:U$13)-RANK(U9,U$8:U$13,0))/(COUNT(U$8:U$13)-1))) | AG9: =IF(OR($A9="",V9=""),"",IF(COUNT(V$8:V$13)<2,1,(COUNT(V$8:V$13)-RANK(V9,V$8:V$13,0))/(COUNT(V$8:V$13)-1)))
B10: =IF($A10="","",COUNTIF(ZIPs!$A$8:$A$107,$A10)) | C10: =IF($A10="","",IF($B10=0,"",IFERROR(AVERAGEIFS(ZIPs!$D$8:$D$107,ZIPs!$A$8:$A$107,$A10),""))) | D10: =IF($A10="","",IF($B10=0,"",SUMIFS(ZIPs!$E$8:$E$107,ZIPs!$A$8:$A$107,$A10))) | E10: =IF($A10="","",IF($B10=0,"",IFERROR(AVERAGEIFS(ZIPs!$G$8:$G$107,ZIPs!$A$8:$A$107,$A10),""))) | F10: =IF($A10="","",IF($B10=0,"",IFERROR(AVERAGEIFS(ZIPs!$J$8:$J$107,ZIPs!$A$8:$A$107,$A10),""))) | G10: =IF($A10="","",IF($B10=0,"",IFERROR(AVERAGEIFS(ZIPs!$S$8:$S$107,ZIPs!$A$8:$A$107,$A10),""))) | H10: =IF($A10="","",IF($B10=0,"",IFERROR(AVERAGEIFS(ZIPs!$T$8:$T$107,ZIPs!$A$8:$A$107,$A10),""))) | I10: =IF($A10="","",COUNTIF('Past Flips'!$A$8:$A$307,$A10)+COUNTIFS('Flip Candidates'!$A$8:$A$207,$A10,'Flip Candidates'!$O$8:$O$207,"Likely flip")) | J10: =IF(OR($A10="",D10="",D10=0),"",I10/(D10*4)) | K10: =IF($A10="","",IFERROR((SUMIFS('Past Flips'!$T$8:$T$307,'Past Flips'!$A$8:$A$307,$A10)+SUMIFS('Flip Candidates'!$R$8:$R$207,'Flip Candidates'!$A$8:$A$207,$A10,'Flip Candidates'!$O$8:$O$207,"Likely flip"))/(COUNTIFS('Past Flips'!$A$8:$A$307,$A10,'Past Flips'!$T$8:$T$307,"<>")+COUNTIFS('Flip Candidates'!$A$8:$A$207,$A10,'Flip Candidates'!$O$8:$O$207,"Likely flip")),"")) | L10: =IF($A10="","",COUNTIF('Listing Watch'!$A$8:$A$307,$A10)) | M10: =IF($A10="","",IFERROR(AVERAGEIFS('Listing Watch'!$S$8:$S$307,'Listing Watch'!$A$8:$A$307,$A10),"")) | N10: =IF(OR($A10="",L10=0),"",COUNTIFS('Listing Watch'!$A$8:$A$307,$A10,'Listing Watch'!$R$8:$R$307,">0")/L10) | O10: =IF($A10="","",COUNTIF(Calls!$A$8:$A$307,$A10)) | P10: =IF($A10="","",IFERROR(AVERAGEIFS(Calls!$K$8:$K$307,Calls!$A$8:$A$307,$A10),"")) | Q10: =IF($A10="","",IFERROR(AVERAGEIFS(Calls!$G$8:$G$307,Calls!$A$8:$A$307,$A10),"")) | R10: =IF($A10="","",IFERROR(AVERAGEIFS(Calls!$H$8:$H$307,Calls!$A$8:$A$307,$A10),"")) | S10: =IF($A10="","",IF(COUNTIF(Competition!$A$8:$A$207,$A10)=0,"",COUNTIF(Competition!$A$8:$A$207,$A10))) | W10: =IF($A10="","",IFERROR(ROUND(100*SUMPRODUCT($X$6:$AG$6,X10:AG10)/SUMPRODUCT($X$6:$AG$6,--(X10:AG10<>"")),0),"")) | X10: =IF(OR($A10="",D10=""),"",IF(COUNT(D$8:D$13)<2,1,(COUNT(D$8:D$13)-RANK(D10,D$8:D$13,0))/(COUNT(D$8:D$13)-1))) | Y10: =IF(OR($A10="",E10=""),"",IF(COUNT(E$8:E$13)<2,1,(COUNT(E$8:E$13)-RANK(E10,E$8:E$13,1))/(COUNT(E$8:E$13)-1))) | Z10: =IF(OR($A10="",F10=""),"",IF(COUNT(F$8:F$13)<2,1,(COUNT(F$8:F$13)-RANK(F10,F$8:F$13,0))/(COUNT(F$8:F$13)-1))) | AA10: =IF(OR($A10="",G10=""),"",IF(COUNT(G$8:G$13)<2,1,(COUNT(G$8:G$13)-RANK(G10,G$8:G$13,0))/(COUNT(G$8:G$13)-1))) | AB10: =IF(OR($A10="",J10=""),"",IF(COUNT(J$8:J$13)<2,1,(COUNT(J$8:J$13)-RANK(J10,J$8:J$13,1))/(COUNT(J$8:J$13)-1))) | AC10: =IF(OR($A10="",P10=""),"",IF(COUNT(P$8:P$13)<2,1,(COUNT(P$8:P$13)-RANK(P10,P$8:P$13,1))/(COUNT(P$8:P$13)-1))) | AD10: =IF(OR($A10="",S10=""),"",IF(COUNT(S$8:S$13)<2,1,(COUNT(S$8:S$13)-RANK(S10,S$8:S$13,1))/(COUNT(S$8:S$13)-1))) | AE10: =IF(OR($A10="",T10=""),"",IF(COUNT(T$8:T$13)<2,1,(COUNT(T$8:T$13)-RANK(T10,T$8:T$13,0))/(COUNT(T$8:T$13)-1))) | AF10: =IF(OR($A10="",U10=""),"",IF(COUNT(U$8:U$13)<2,1,(COUNT(U$8:U$13)-RANK(U10,U$8:U$13,0))/(COUNT(U$8:U$13)-1))) | AG10: =IF(OR($A10="",V10=""),"",IF(COUNT(V$8:V$13)<2,1,(COUNT(V$8:V$13)-RANK(V10,V$8:V$13,0))/(COUNT(V$8:V$13)-1)))
B11: =IF($A11="","",COUNTIF(ZIPs!$A$8:$A$107,$A11)) | C11: =IF($A11="","",IF($B11=0,"",IFERROR(AVERAGEIFS(ZIPs!$D$8:$D$107,ZIPs!$A$8:$A$107,$A11),""))) | D11: =IF($A11="","",IF($B11=0,"",SUMIFS(ZIPs!$E$8:$E$107,ZIPs!$A$8:$A$107,$A11))) | E11: =IF($A11="","",IF($B11=0,"",IFERROR(AVERAGEIFS(ZIPs!$G$8:$G$107,ZIPs!$A$8:$A$107,$A11),""))) | F11: =IF($A11="","",IF($B11=0,"",IFERROR(AVERAGEIFS(ZIPs!$J$8:$J$107,ZIPs!$A$8:$A$107,$A11),""))) | G11: =IF($A11="","",IF($B11=0,"",IFERROR(AVERAGEIFS(ZIPs!$S$8:$S$107,ZIPs!$A$8:$A$107,$A11),""))) | H11: =IF($A11="","",IF($B11=0,"",IFERROR(AVERAGEIFS(ZIPs!$T$8:$T$107,ZIPs!$A$8:$A$107,$A11),""))) | I11: =IF($A11="","",COUNTIF('Past Flips'!$A$8:$A$307,$A11)+COUNTIFS('Flip Candidates'!$A$8:$A$207,$A11,'Flip Candidates'!$O$8:$O$207,"Likely flip")) | J11: =IF(OR($A11="",D11="",D11=0),"",I11/(D11*4)) | K11: =IF($A11="","",IFERROR((SUMIFS('Past Flips'!$T$8:$T$307,'Past Flips'!$A$8:$A$307,$A11)+SUMIFS('Flip Candidates'!$R$8:$R$207,'Flip Candidates'!$A$8:$A$207,$A11,'Flip Candidates'!$O$8:$O$207,"Likely flip"))/(COUNTIFS('Past Flips'!$A$8:$A$307,$A11,'Past Flips'!$T$8:$T$307,"<>")+COUNTIFS('Flip Candidates'!$A$8:$A$207,$A11,'Flip Candidates'!$O$8:$O$207,"Likely flip")),"")) | L11: =IF($A11="","",COUNTIF('Listing Watch'!$A$8:$A$307,$A11)) | M11: =IF($A11="","",IFERROR(AVERAGEIFS('Listing Watch'!$S$8:$S$307,'Listing Watch'!$A$8:$A$307,$A11),"")) | N11: =IF(OR($A11="",L11=0),"",COUNTIFS('Listing Watch'!$A$8:$A$307,$A11,'Listing Watch'!$R$8:$R$307,">0")/L11) | O11: =IF($A11="","",COUNTIF(Calls!$A$8:$A$307,$A11)) | P11: =IF($A11="","",IFERROR(AVERAGEIFS(Calls!$K$8:$K$307,Calls!$A$8:$A$307,$A11),"")) | Q11: =IF($A11="","",IFERROR(AVERAGEIFS(Calls!$G$8:$G$307,Calls!$A$8:$A$307,$A11),"")) | R11: =IF($A11="","",IFERROR(AVERAGEIFS(Calls!$H$8:$H$307,Calls!$A$8:$A$307,$A11),"")) | S11: =IF($A11="","",IF(COUNTIF(Competition!$A$8:$A$207,$A11)=0,"",COUNTIF(Competition!$A$8:$A$207,$A11))) | W11: =IF($A11="","",IFERROR(ROUND(100*SUMPRODUCT($X$6:$AG$6,X11:AG11)/SUMPRODUCT($X$6:$AG$6,--(X11:AG11<>"")),0),"")) | X11: =IF(OR($A11="",D11=""),"",IF(COUNT(D$8:D$13)<2,1,(COUNT(D$8:D$13)-RANK(D11,D$8:D$13,0))/(COUNT(D$8:D$13)-1))) | Y11: =IF(OR($A11="",E11=""),"",IF(COUNT(E$8:E$13)<2,1,(COUNT(E$8:E$13)-RANK(E11,E$8:E$13,1))/(COUNT(E$8:E$13)-1))) | Z11: =IF(OR($A11="",F11=""),"",IF(COUNT(F$8:F$13)<2,1,(COUNT(F$8:F$13)-RANK(F11,F$8:F$13,0))/(COUNT(F$8:F$13)-1))) | AA11: =IF(OR($A11="",G11=""),"",IF(COUNT(G$8:G$13)<2,1,(COUNT(G$8:G$13)-RANK(G11,G$8:G$13,0))/(COUNT(G$8:G$13)-1))) | AB11: =IF(OR($A11="",J11=""),"",IF(COUNT(J$8:J$13)<2,1,(COUNT(J$8:J$13)-RANK(J11,J$8:J$13,1))/(COUNT(J$8:J$13)-1))) | AC11: =IF(OR($A11="",P11=""),"",IF(COUNT(P$8:P$13)<2,1,(COUNT(P$8:P$13)-RANK(P11,P$8:P$13,1))/(COUNT(P$8:P$13)-1))) | AD11: =IF(OR($A11="",S11=""),"",IF(COUNT(S$8:S$13)<2,1,(COUNT(S$8:S$13)-RANK(S11,S$8:S$13,1))/(COUNT(S$8:S$13)-1))) | AE11: =IF(OR($A11="",T11=""),"",IF(COUNT(T$8:T$13)<2,1,(COUNT(T$8:T$13)-RANK(T11,T$8:T$13,0))/(COUNT(T$8:T$13)-1))) | AF11: =IF(OR($A11="",U11=""),"",IF(COUNT(U$8:U$13)<2,1,(COUNT(U$8:U$13)-RANK(U11,U$8:U$13,0))/(COUNT(U$8:U$13)-1))) | AG11: =IF(OR($A11="",V11=""),"",IF(COUNT(V$8:V$13)<2,1,(COUNT(V$8:V$13)-RANK(V11,V$8:V$13,0))/(COUNT(V$8:V$13)-1)))
B12: =IF($A12="","",COUNTIF(ZIPs!$A$8:$A$107,$A12)) | C12: =IF($A12="","",IF($B12=0,"",IFERROR(AVERAGEIFS(ZIPs!$D$8:$D$107,ZIPs!$A$8:$A$107,$A12),""))) | D12: =IF($A12="","",IF($B12=0,"",SUMIFS(ZIPs!$E$8:$E$107,ZIPs!$A$8:$A$107,$A12))) | E12: =IF($A12="","",IF($B12=0,"",IFERROR(AVERAGEIFS(ZIPs!$G$8:$G$107,ZIPs!$A$8:$A$107,$A12),""))) | F12: =IF($A12="","",IF($B12=0,"",IFERROR(AVERAGEIFS(ZIPs!$J$8:$J$107,ZIPs!$A$8:$A$107,$A12),""))) | G12: =IF($A12="","",IF($B12=0,"",IFERROR(AVERAGEIFS(ZIPs!$S$8:$S$107,ZIPs!$A$8:$A$107,$A12),""))) | H12: =IF($A12="","",IF($B12=0,"",IFERROR(AVERAGEIFS(ZIPs!$T$8:$T$107,ZIPs!$A$8:$A$107,$A12),""))) | I12: =IF($A12="","",COUNTIF('Past Flips'!$A$8:$A$307,$A12)+COUNTIFS('Flip Candidates'!$A$8:$A$207,$A12,'Flip Candidates'!$O$8:$O$207,"Likely flip")) | J12: =IF(OR($A12="",D12="",D12=0),"",I12/(D12*4)) | K12: =IF($A12="","",IFERROR((SUMIFS('Past Flips'!$T$8:$T$307,'Past Flips'!$A$8:$A$307,$A12)+SUMIFS('Flip Candidates'!$R$8:$R$207,'Flip Candidates'!$A$8:$A$207,$A12,'Flip Candidates'!$O$8:$O$207,"Likely flip"))/(COUNTIFS('Past Flips'!$A$8:$A$307,$A12,'Past Flips'!$T$8:$T$307,"<>")+COUNTIFS('Flip Candidates'!$A$8:$A$207,$A12,'Flip Candidates'!$O$8:$O$207,"Likely flip")),"")) | L12: =IF($A12="","",COUNTIF('Listing Watch'!$A$8:$A$307,$A12)) | M12: =IF($A12="","",IFERROR(AVERAGEIFS('Listing Watch'!$S$8:$S$307,'Listing Watch'!$A$8:$A$307,$A12),"")) | N12: =IF(OR($A12="",L12=0),"",COUNTIFS('Listing Watch'!$A$8:$A$307,$A12,'Listing Watch'!$R$8:$R$307,">0")/L12) | O12: =IF($A12="","",COUNTIF(Calls!$A$8:$A$307,$A12)) | P12: =IF($A12="","",IFERROR(AVERAGEIFS(Calls!$K$8:$K$307,Calls!$A$8:$A$307,$A12),"")) | Q12: =IF($A12="","",IFERROR(AVERAGEIFS(Calls!$G$8:$G$307,Calls!$A$8:$A$307,$A12),"")) | R12: =IF($A12="","",IFERROR(AVERAGEIFS(Calls!$H$8:$H$307,Calls!$A$8:$A$307,$A12),"")) | S12: =IF($A12="","",IF(COUNTIF(Competition!$A$8:$A$207,$A12)=0,"",COUNTIF(Competition!$A$8:$A$207,$A12))) | W12: =IF($A12="","",IFERROR(ROUND(100*SUMPRODUCT($X$6:$AG$6,X12:AG12)/SUMPRODUCT($X$6:$AG$6,--(X12:AG12<>"")),0),"")) | X12: =IF(OR($A12="",D12=""),"",IF(COUNT(D$8:D$13)<2,1,(COUNT(D$8:D$13)-RANK(D12,D$8:D$13,0))/(COUNT(D$8:D$13)-1))) | Y12: =IF(OR($A12="",E12=""),"",IF(COUNT(E$8:E$13)<2,1,(COUNT(E$8:E$13)-RANK(E12,E$8:E$13,1))/(COUNT(E$8:E$13)-1))) | Z12: =IF(OR($A12="",F12=""),"",IF(COUNT(F$8:F$13)<2,1,(COUNT(F$8:F$13)-RANK(F12,F$8:F$13,0))/(COUNT(F$8:F$13)-1))) | AA12: =IF(OR($A12="",G12=""),"",IF(COUNT(G$8:G$13)<2,1,(COUNT(G$8:G$13)-RANK(G12,G$8:G$13,0))/(COUNT(G$8:G$13)-1))) | AB12: =IF(OR($A12="",J12=""),"",IF(COUNT(J$8:J$13)<2,1,(COUNT(J$8:J$13)-RANK(J12,J$8:J$13,1))/(COUNT(J$8:J$13)-1))) | AC12: =IF(OR($A12="",P12=""),"",IF(COUNT(P$8:P$13)<2,1,(COUNT(P$8:P$13)-RANK(P12,P$8:P$13,1))/(COUNT(P$8:P$13)-1))) | AD12: =IF(OR($A12="",S12=""),"",IF(COUNT(S$8:S$13)<2,1,(COUNT(S$8:S$13)-RANK(S12,S$8:S$13,1))/(COUNT(S$8:S$13)-1))) | AE12: =IF(OR($A12="",T12=""),"",IF(COUNT(T$8:T$13)<2,1,(COUNT(T$8:T$13)-RANK(T12,T$8:T$13,0))/(COUNT(T$8:T$13)-1))) | AF12: =IF(OR($A12="",U12=""),"",IF(COUNT(U$8:U$13)<2,1,(COUNT(U$8:U$13)-RANK(U12,U$8:U$13,0))/(COUNT(U$8:U$13)-1))) | AG12: =IF(OR($A12="",V12=""),"",IF(COUNT(V$8:V$13)<2,1,(COUNT(V$8:V$13)-RANK(V12,V$8:V$13,0))/(COUNT(V$8:V$13)-1)))
B13: =IF($A13="","",COUNTIF(ZIPs!$A$8:$A$107,$A13)) | C13: =IF($A13="","",IF($B13=0,"",IFERROR(AVERAGEIFS(ZIPs!$D$8:$D$107,ZIPs!$A$8:$A$107,$A13),""))) | D13: =IF($A13="","",IF($B13=0,"",SUMIFS(ZIPs!$E$8:$E$107,ZIPs!$A$8:$A$107,$A13))) | E13: =IF($A13="","",IF($B13=0,"",IFERROR(AVERAGEIFS(ZIPs!$G$8:$G$107,ZIPs!$A$8:$A$107,$A13),""))) | F13: =IF($A13="","",IF($B13=0,"",IFERROR(AVERAGEIFS(ZIPs!$J$8:$J$107,ZIPs!$A$8:$A$107,$A13),""))) | G13: =IF($A13="","",IF($B13=0,"",IFERROR(AVERAGEIFS(ZIPs!$S$8:$S$107,ZIPs!$A$8:$A$107,$A13),""))) | H13: =IF($A13="","",IF($B13=0,"",IFERROR(AVERAGEIFS(ZIPs!$T$8:$T$107,ZIPs!$A$8:$A$107,$A13),""))) | I13: =IF($A13="","",COUNTIF('Past Flips'!$A$8:$A$307,$A13)+COUNTIFS('Flip Candidates'!$A$8:$A$207,$A13,'Flip Candidates'!$O$8:$O$207,"Likely flip")) | J13: =IF(OR($A13="",D13="",D13=0),"",I13/(D13*4)) | K13: =IF($A13="","",IFERROR((SUMIFS('Past Flips'!$T$8:$T$307,'Past Flips'!$A$8:$A$307,$A13)+SUMIFS('Flip Candidates'!$R$8:$R$207,'Flip Candidates'!$A$8:$A$207,$A13,'Flip Candidates'!$O$8:$O$207,"Likely flip"))/(COUNTIFS('Past Flips'!$A$8:$A$307,$A13,'Past Flips'!$T$8:$T$307,"<>")+COUNTIFS('Flip Candidates'!$A$8:$A$207,$A13,'Flip Candidates'!$O$8:$O$207,"Likely flip")),"")) | L13: =IF($A13="","",COUNTIF('Listing Watch'!$A$8:$A$307,$A13)) | M13: =IF($A13="","",IFERROR(AVERAGEIFS('Listing Watch'!$S$8:$S$307,'Listing Watch'!$A$8:$A$307,$A13),"")) | N13: =IF(OR($A13="",L13=0),"",COUNTIFS('Listing Watch'!$A$8:$A$307,$A13,'Listing Watch'!$R$8:$R$307,">0")/L13) | O13: =IF($A13="","",COUNTIF(Calls!$A$8:$A$307,$A13)) | P13: =IF($A13="","",IFERROR(AVERAGEIFS(Calls!$K$8:$K$307,Calls!$A$8:$A$307,$A13),"")) | Q13: =IF($A13="","",IFERROR(AVERAGEIFS(Calls!$G$8:$G$307,Calls!$A$8:$A$307,$A13),"")) | R13: =IF($A13="","",IFERROR(AVERAGEIFS(Calls!$H$8:$H$307,Calls!$A$8:$A$307,$A13),"")) | S13: =IF($A13="","",IF(COUNTIF(Competition!$A$8:$A$207,$A13)=0,"",COUNTIF(Competition!$A$8:$A$207,$A13))) | W13: =IF($A13="","",IFERROR(ROUND(100*SUMPRODUCT($X$6:$AG$6,X13:AG13)/SUMPRODUCT($X$6:$AG$6,--(X13:AG13<>"")),0),"")) | X13: =IF(OR($A13="",D13=""),"",IF(COUNT(D$8:D$13)<2,1,(COUNT(D$8:D$13)-RANK(D13,D$8:D$13,0))/(COUNT(D$8:D$13)-1))) | Y13: =IF(OR($A13="",E13=""),"",IF(COUNT(E$8:E$13)<2,1,(COUNT(E$8:E$13)-RANK(E13,E$8:E$13,1))/(COUNT(E$8:E$13)-1))) | Z13: =IF(OR($A13="",F13=""),"",IF(COUNT(F$8:F$13)<2,1,(COUNT(F$8:F$13)-RANK(F13,F$8:F$13,0))/(COUNT(F$8:F$13)-1))) | AA13: =IF(OR($A13="",G13=""),"",IF(COUNT(G$8:G$13)<2,1,(COUNT(G$8:G$13)-RANK(G13,G$8:G$13,0))/(COUNT(G$8:G$13)-1))) | AB13: =IF(OR($A13="",J13=""),"",IF(COUNT(J$8:J$13)<2,1,(COUNT(J$8:J$13)-RANK(J13,J$8:J$13,1))/(COUNT(J$8:J$13)-1))) | AC13: =IF(OR($A13="",P13=""),"",IF(COUNT(P$8:P$13)<2,1,(COUNT(P$8:P$13)-RANK(P13,P$8:P$13,1))/(COUNT(P$8:P$13)-1))) | AD13: =IF(OR($A13="",S13=""),"",IF(COUNT(S$8:S$13)<2,1,(COUNT(S$8:S$13)-RANK(S13,S$8:S$13,1))/(COUNT(S$8:S$13)-1))) | AE13: =IF(OR($A13="",T13=""),"",IF(COUNT(T$8:T$13)<2,1,(COUNT(T$8:T$13)-RANK(T13,T$8:T$13,0))/(COUNT(T$8:T$13)-1))) | AF13: =IF(OR($A13="",U13=""),"",IF(COUNT(U$8:U$13)<2,1,(COUNT(U$8:U$13)-RANK(U13,U$8:U$13,0))/(COUNT(U$8:U$13)-1))) | AG13: =IF(OR($A13="",V13=""),"",IF(COUNT(V$8:V$13)<2,1,(COUNT(V$8:V$13)-RANK(V13,V$8:V$13,0))/(COUNT(V$8:V$13)-1)))
A16: Ready check: don't buy in a metro until every box says Yes
A17: Metro | B17: Data spot-checked vs. Redfin (Y/N) | C17: 10+ local calls | D17: 3+ agents called | E17: A lender reviewed a real deal (Y/N) | F17: 10+ paper flips | G17: Paper resale miss ≤ 10% | H17: Visited in person (Y/N) | I17: READY?
A18: =IF($A$8="","",$A$8) -> Sampleville, OH | C18: =IF($A18="","",IF(COUNTIF(Calls!$A$8:$A$307,$A18)>=10,"Yes","No ("&COUNTIF(Calls!$A$8:$A$307,$A18)&"/10)")) -> No (1/10) | D18: =IF($A18="","",IF(COUNTIFS(Calls!$A$8:$A$307,$A18,Calls!$D$8:$D$307,"Agent")>=3,"Yes","No ("&COUNTIFS(Calls!$A$8:$A$307,$A18,Calls!$D$8:$D$307,"Agent")&"/3)")) -> No (1/3) | F18: =IF($A18="","",IF(COUNTIF('Paper Flips'!$B$8:$B$307,$A18)>=10,"Yes","No ("&COUNTIF('Paper Flips'!$B$8:$B$307,$A18)&"/10)")) -> No (1/10) | G18: =IF($A18="","",IF(COUNTIFS('Paper Flips'!$B$8:$B$307,$A18,'Paper Flips'!$O$8:$O$307,"<>")=0,"No data yet",IF(AVERAGEIFS('Paper Flips'!$O$8:$O$307,'Paper Flips'!$B$8:$B$307,$A18)<=0.1,"Yes","No ("&TEXT(AVERAGEIFS('Paper Flips'!$O$8:$O$307,'Paper Flips'!$B$8:$B$307,$A18),"0%")&")"))) -> Yes | I18: =IF($A18="","",IF(AND(UPPER(B18)="Y",C18="Yes",D18="Yes",UPPER(E18)="Y",F18="Yes",G18="Yes",UPPER(H18)="Y"),"READY","Not yet")) -> Not yet
A19: =IF($A$9="","",$A$9) | C19: =IF($A19="","",IF(COUNTIF(Calls!$A$8:$A$307,$A19)>=10,"Yes","No ("&COUNTIF(Calls!$A$8:$A$307,$A19)&"/10)")) | D19: =IF($A19="","",IF(COUNTIFS(Calls!$A$8:$A$307,$A19,Calls!$D$8:$D$307,"Agent")>=3,"Yes","No ("&COUNTIFS(Calls!$A$8:$A$307,$A19,Calls!$D$8:$D$307,"Agent")&"/3)")) | F19: =IF($A19="","",IF(COUNTIF('Paper Flips'!$B$8:$B$307,$A19)>=10,"Yes","No ("&COUNTIF('Paper Flips'!$B$8:$B$307,$A19)&"/10)")) | G19: =IF($A19="","",IF(COUNTIFS('Paper Flips'!$B$8:$B$307,$A19,'Paper Flips'!$O$8:$O$307,"<>")=0,"No data yet",IF(AVERAGEIFS('Paper Flips'!$O$8:$O$307,'Paper Flips'!$B$8:$B$307,$A19)<=0.1,"Yes","No ("&TEXT(AVERAGEIFS('Paper Flips'!$O$8:$O$307,'Paper Flips'!$B$8:$B$307,$A19),"0%")&")"))) | I19: =IF($A19="","",IF(AND(UPPER(B19)="Y",C19="Yes",D19="Yes",UPPER(E19)="Y",F19="Yes",G19="Yes",UPPER(H19)="Y"),"READY","Not yet"))
A20: =IF($A$10="","",$A$10) | C20: =IF($A20="","",IF(COUNTIF(Calls!$A$8:$A$307,$A20)>=10,"Yes","No ("&COUNTIF(Calls!$A$8:$A$307,$A20)&"/10)")) | D20: =IF($A20="","",IF(COUNTIFS(Calls!$A$8:$A$307,$A20,Calls!$D$8:$D$307,"Agent")>=3,"Yes","No ("&COUNTIFS(Calls!$A$8:$A$307,$A20,Calls!$D$8:$D$307,"Agent")&"/3)")) | F20: =IF($A20="","",IF(COUNTIF('Paper Flips'!$B$8:$B$307,$A20)>=10,"Yes","No ("&COUNTIF('Paper Flips'!$B$8:$B$307,$A20)&"/10)")) | G20: =IF($A20="","",IF(COUNTIFS('Paper Flips'!$B$8:$B$307,$A20,'Paper Flips'!$O$8:$O$307,"<>")=0,"No data yet",IF(AVERAGEIFS('Paper Flips'!$O$8:$O$307,'Paper Flips'!$B$8:$B$307,$A20)<=0.1,"Yes","No ("&TEXT(AVERAGEIFS('Paper Flips'!$O$8:$O$307,'Paper Flips'!$B$8:$B$307,$A20),"0%")&")"))) | I20: =IF($A20="","",IF(AND(UPPER(B20)="Y",C20="Yes",D20="Yes",UPPER(E20)="Y",F20="Yes",G20="Yes",UPPER(H20)="Y"),"READY","Not yet"))
A21: =IF($A$11="","",$A$11) | C21: =IF($A21="","",IF(COUNTIF(Calls!$A$8:$A$307,$A21)>=10,"Yes","No ("&COUNTIF(Calls!$A$8:$A$307,$A21)&"/10)")) | D21: =IF($A21="","",IF(COUNTIFS(Calls!$A$8:$A$307,$A21,Calls!$D$8:$D$307,"Agent")>=3,"Yes","No ("&COUNTIFS(Calls!$A$8:$A$307,$A21,Calls!$D$8:$D$307,"Agent")&"/3)")) | F21: =IF($A21="","",IF(COUNTIF('Paper Flips'!$B$8:$B$307,$A21)>=10,"Yes","No ("&COUNTIF('Paper Flips'!$B$8:$B$307,$A21)&"/10)")) | G21: =IF($A21="","",IF(COUNTIFS('Paper Flips'!$B$8:$B$307,$A21,'Paper Flips'!$O$8:$O$307,"<>")=0,"No data yet",IF(AVERAGEIFS('Paper Flips'!$O$8:$O$307,'Paper Flips'!$B$8:$B$307,$A21)<=0.1,"Yes","No ("&TEXT(AVERAGEIFS('Paper Flips'!$O$8:$O$307,'Paper Flips'!$B$8:$B$307,$A21),"0%")&")"))) | I21: =IF($A21="","",IF(AND(UPPER(B21)="Y",C21="Yes",D21="Yes",UPPER(E21)="Y",F21="Yes",G21="Yes",UPPER(H21)="Y"),"READY","Not yet"))
A22: =IF($A$12="","",$A$12) | C22: =IF($A22="","",IF(COUNTIF(Calls!$A$8:$A$307,$A22)>=10,"Yes","No ("&COUNTIF(Calls!$A$8:$A$307,$A22)&"/10)")) | D22: =IF($A22="","",IF(COUNTIFS(Calls!$A$8:$A$307,$A22,Calls!$D$8:$D$307,"Agent")>=3,"Yes","No ("&COUNTIFS(Calls!$A$8:$A$307,$A22,Calls!$D$8:$D$307,"Agent")&"/3)")) | F22: =IF($A22="","",IF(COUNTIF('Paper Flips'!$B$8:$B$307,$A22)>=10,"Yes","No ("&COUNTIF('Paper Flips'!$B$8:$B$307,$A22)&"/10)")) | G22: =IF($A22="","",IF(COUNTIFS('Paper Flips'!$B$8:$B$307,$A22,'Paper Flips'!$O$8:$O$307,"<>")=0,"No data yet",IF(AVERAGEIFS('Paper Flips'!$O$8:$O$307,'Paper Flips'!$B$8:$B$307,$A22)<=0.1,"Yes","No ("&TEXT(AVERAGEIFS('Paper Flips'!$O$8:$O$307,'Paper Flips'!$B$8:$B$307,$A22),"0%")&")"))) | I22: =IF($A22="","",IF(AND(UPPER(B22)="Y",C22="Yes",D22="Yes",UPPER(E22)="Y",F22="Yes",G22="Yes",UPPER(H22)="Y"),"READY","Not yet"))
A23: =IF($A$13="","",$A$13) | C23: =IF($A23="","",IF(COUNTIF(Calls!$A$8:$A$307,$A23)>=10,"Yes","No ("&COUNTIF(Calls!$A$8:$A$307,$A23)&"/10)")) | D23: =IF($A23="","",IF(COUNTIFS(Calls!$A$8:$A$307,$A23,Calls!$D$8:$D$307,"Agent")>=3,"Yes","No ("&COUNTIFS(Calls!$A$8:$A$307,$A23,Calls!$D$8:$D$307,"Agent")&"/3)")) | F23: =IF($A23="","",IF(COUNTIF('Paper Flips'!$B$8:$B$307,$A23)>=10,"Yes","No ("&COUNTIF('Paper Flips'!$B$8:$B$307,$A23)&"/10)")) | G23: =IF($A23="","",IF(COUNTIFS('Paper Flips'!$B$8:$B$307,$A23,'Paper Flips'!$O$8:$O$307,"<>")=0,"No data yet",IF(AVERAGEIFS('Paper Flips'!$O$8:$O$307,'Paper Flips'!$B$8:$B$307,$A23)<=0.1,"Yes","No ("&TEXT(AVERAGEIFS('Paper Flips'!$O$8:$O$307,'Paper Flips'!$B$8:$B$307,$A23),"0%")&")"))) | I23: =IF($A23="","",IF(AND(UPPER(B23)="Y",C23="Yes",D23="Yes",UPPER(E23)="Y",F23="Yes",G23="Yes",UPPER(H23)="Y"),"READY","Not yet"))
A25: Paper resale miss uses the "Miss (+/-)" column in Paper Flips, which needs a renovated resale or comp you found later.

Sheet ZIPs
A1: ZIPs
A2: One row per ZIP. Click the links on the right, copy the numbers into the yellow cells. Keep "Metro" spelled exactly as in the Metros tab.
A6: Where | D6: From Redfin (ZIP page) | K6: Rent | L6: From the Census | P6: Your check | R6: Calculated | X6: Open the source
A7: Metro | B7: ZIP | C7: City | D7: Median sale price ($) | E7: Homes sold, last 3 mo | F7: Active listings now | G7: Median days on market | H7: Sale-to-list | I7: Sold above list | J7: Price change, 1 yr | K7: Typical rent, 3-bed ($/mo) | L7: Median year built | M7: Owner-occupied single-family homes (B25032 line 3) | N7: Rented single-family homes (B25032 line 14) | O7: Median household income ($) | P7: Checked on | Q7: Source / notes | R7: Months of supply | S7: Rent yield (gross) | T7: Single-family homes rented out | U7: Flips found, 12 mo | V7: Flips as % of sales (est.) | W7: Listings watched | X7: Redfin | Y7: Census B25032 | Z7: Census Reporter
A8: Sampleville, OH | B8: EX001 | C8: Sampleville | D8: 185000 | E8: 42 | F8: 38 | G8: 34 | H8: 0.975 | I8: 0.22 | J8: 0.041 | K8: 1450 | L8: 1958 | M8: 2410 | N8: 520 | O8: 61500 | P8: 46310 | Q8: EXAMPLE row: delete me | R8: =IF(OR(E8="",F8="",E8=0),"",F8/(E8/3)) -> 2.7142857 | S8: =IF(OR(D8="",K8="",D8=0),"",K8*12/D8) -> 0.094054054 | T8: =IF(OR(M8="",N8=""),"",IF(M8+N8=0,"",N8/(M8+N8))) -> 0.1774744 | U8: =IF(B8="","",COUNTIF('Past Flips'!$B$8:$B$307,B8)+COUNTIFS('Flip Candidates'!$B$8:$B$207,B8,'Flip Candidates'!$O$8:$O$207,"Likely flip")) -> 2 | V8: =IF(OR(U8="",E8="",E8=0),"",U8/(E8*4)) -> 0.011904762 | W8: =IF(B8="","",COUNTIF('Listing Watch'!$B$8:$B$307,B8)) -> 1 | X8: =IF(B8="","",HYPERLINK("https://www.redfin.com/zipcode/"&B8&"/housing-market","Redfin")) -> Redfin | Y8: =IF(B8="","",HYPERLINK("https://data.census.gov/table/ACSDT5Y2024.B25032?g=860XX00US"&B8,"B25032")) -> B25032 | Z8: =IF(B8="","",HYPERLINK("https://censusreporter.org/profiles/86000US"&B8&"-"&B8&"/","Profile")) -> Profile
R9: =IF(OR(E9="",F9="",E9=0),"",F9/(E9/3)) | S9: =IF(OR(D9="",K9="",D9=0),"",K9*12/D9) | T9: =IF(OR(M9="",N9=""),"",IF(M9+N9=0,"",N9/(M9+N9))) | U9: =IF(B9="","",COUNTIF('Past Flips'!$B$8:$B$307,B9)+COUNTIFS('Flip Candidates'!$B$8:$B$207,B9,'Flip Candidates'!$O$8:$O$207,"Likely flip")) | V9: =IF(OR(U9="",E9="",E9=0),"",U9/(E9*4)) | W9: =IF(B9="","",COUNTIF('Listing Watch'!$B$8:$B$307,B9)) | X9: =IF(B9="","",HYPERLINK("https://www.redfin.com/zipcode/"&B9&"/housing-market","Redfin")) | Y9: =IF(B9="","",HYPERLINK("https://data.census.gov/table/ACSDT5Y2024.B25032?g=860XX00US"&B9,"B25032")) | Z9: =IF(B9="","",HYPERLINK("https://censusreporter.org/profiles/86000US"&B9&"-"&B9&"/","Profile"))
R10: =IF(OR(E10="",F10="",E10=0),"",F10/(E10/3)) | S10: =IF(OR(D10="",K10="",D10=0),"",K10*12/D10) | T10: =IF(OR(M10="",N10=""),"",IF(M10+N10=0,"",N10/(M10+N10))) | U10: =IF(B10="","",COUNTIF('Past Flips'!$B$8:$B$307,B10)+COUNTIFS('Flip Candidates'!$B$8:$B$207,B10,'Flip Candidates'!$O$8:$O$207,"Likely flip")) | V10: =IF(OR(U10="",E10="",E10=0),"",U10/(E10*4)) | W10: =IF(B10="","",COUNTIF('Listing Watch'!$B$8:$B$307,B10)) | X10: =IF(B10="","",HYPERLINK("https://www.redfin.com/zipcode/"&B10&"/housing-market","Redfin")) | Y10: =IF(B10="","",HYPERLINK("https://data.census.gov/table/ACSDT5Y2024.B25032?g=860XX00US"&B10,"B25032")) | Z10: =IF(B10="","",HYPERLINK("https://censusreporter.org/profiles/86000US"&B10&"-"&B10&"/","Profile"))
R11: =IF(OR(E11="",F11="",E11=0),"",F11/(E11/3)) | S11: =IF(OR(D11="",K11="",D11=0),"",K11*12/D11) | T11: =IF(OR(M11="",N11=""),"",IF(M11+N11=0,"",N11/(M11+N11))) | U11: =IF(B11="","",COUNTIF('Past Flips'!$B$8:$B$307,B11)+COUNTIFS('Flip Candidates'!$B$8:$B$207,B11,'Flip Candidates'!$O$8:$O$207,"Likely flip")) | V11: =IF(OR(U11="",E11="",E11=0),"",U11/(E11*4)) | W11: =IF(B11="","",COUNTIF('Listing Watch'!$B$8:$B$307,B11)) | X11: =IF(B11="","",HYPERLINK("https://www.redfin.com/zipcode/"&B11&"/housing-market","Redfin")) | Y11: =IF(B11="","",HYPERLINK("https://data.census.gov/table/ACSDT5Y2024.B25032?g=860XX00US"&B11,"B25032")) | Z11: =IF(B11="","",HYPERLINK("https://censusreporter.org/profiles/86000US"&B11&"-"&B11&"/","Profile"))
R12: =IF(OR(E12="",F12="",E12=0),"",F12/(E12/3)) | S12: =IF(OR(D12="",K12="",D12=0),"",K12*12/D12) | T12: =IF(OR(M12="",N12=""),"",IF(M12+N12=0,"",N12/(M12+N12))) | U12: =IF(B12="","",COUNTIF('Past Flips'!$B$8:$B$307,B12)+COUNTIFS('Flip Candidates'!$B$8:$B$207,B12,'Flip Candidates'!$O$8:$O$207,"Likely flip")) | V12: =IF(OR(U12="",E12="",E12=0),"",U12/(E12*4)) | W12: =IF(B12="","",COUNTIF('Listing Watch'!$B$8:$B$307,B12)) | X12: =IF(B12="","",HYPERLINK("https://www.redfin.com/zipcode/"&B12&"/housing-market","Redfin")) | Y12: =IF(B12="","",HYPERLINK("https://data.census.gov/table/ACSDT5Y2024.B25032?g=860XX00US"&B12,"B25032")) | Z12: =IF(B12="","",HYPERLINK("https://censusreporter.org/profiles/86000US"&B12&"-"&B12&"/","Profile"))
R13: =IF(OR(E13="",F13="",E13=0),"",F13/(E13/3)) | S13: =IF(OR(D13="",K13="",D13=0),"",K13*12/D13) | T13: =IF(OR(M13="",N13=""),"",IF(M13+N13=0,"",N13/(M13+N13))) | U13: =IF(B13="","",COUNTIF('Past Flips'!$B$8:$B$307,B13)+COUNTIFS('Flip Candidates'!$B$8:$B$207,B13,'Flip Candidates'!$O$8:$O$207,"Likely flip")) | V13: =IF(OR(U13="",E13="",E13=0),"",U13/(E13*4)) | W13: =IF(B13="","",COUNTIF('Listing Watch'!$B$8:$B$307,B13)) | X13: =IF(B13="","",HYPERLINK("https://www.redfin.com/zipcode/"&B13&"/housing-market","Redfin")) | Y13: =IF(B13="","",HYPERLINK("https://data.census.gov/table/ACSDT5Y2024.B25032?g=860XX00US"&B13,"B25032")) | Z13: =IF(B13="","",HYPERLINK("https://censusreporter.org/profiles/86000US"&B13&"-"&B13&"/","Profile"))
R14: =IF(OR(E14="",F14="",E14=0),"",F14/(E14/3)) | S14: =IF(OR(D14="",K14="",D14=0),"",K14*12/D14) | T14: =IF(OR(M14="",N14=""),"",IF(M14+N14=0,"",N14/(M14+N14))) | U14: =IF(B14="","",COUNTIF('Past Flips'!$B$8:$B$307,B14)+COUNTIFS('Flip Candidates'!$B$8:$B$207,B14,'Flip Candidates'!$O$8:$O$207,"Likely flip")) | V14: =IF(OR(U14="",E14="",E14=0),"",U14/(E14*4)) | W14: =IF(B14="","",COUNTIF('Listing Watch'!$B$8:$B$307,B14)) | X14: =IF(B14="","",HYPERLINK("https://www.redfin.com/zipcode/"&B14&"/housing-market","Redfin")) | Y14: =IF(B14="","",HYPERLINK("https://data.census.gov/table/ACSDT5Y2024.B25032?g=860XX00US"&B14,"B25032")) | Z14: =IF(B14="","",HYPERLINK("https://censusreporter.org/profiles/86000US"&B14&"-"&B14&"/","Profile"))
R15: =IF(OR(E15="",F15="",E15=0),"",F15/(E15/3)) | S15: =IF(OR(D15="",K15="",D15=0),"",K15*12/D15) | T15: =IF(OR(M15="",N15=""),"",IF(M15+N15=0,"",N15/(M15+N15))) | U15: =IF(B15="","",COUNTIF('Past Flips'!$B$8:$B$307,B15)+COUNTIFS('Flip Candidates'!$B$8:$B$207,B15,'Flip Candidates'!$O$8:$O$207,"Likely flip")) | V15: =IF(OR(U15="",E15="",E15=0),"",U15/(E15*4)) | W15: =IF(B15="","",COUNTIF('Listing Watch'!$B$8:$B$307,B15)) | X15: =IF(B15="","",HYPERLINK("https://www.redfin.com/zipcode/"&B15&"/housing-market","Redfin")) | Y15: =IF(B15="","",HYPERLINK("https://data.census.gov/table/ACSDT5Y2024.B25032?g=860XX00US"&B15,"B25032")) | Z15: =IF(B15="","",HYPERLINK("https://censusreporter.org/profiles/86000US"&B15&"-"&B15&"/","Profile"))
R16: =IF(OR(E16="",F16="",E16=0),"",F16/(E16/3)) | S16: =IF(OR(D16="",K16="",D16=0),"",K16*12/D16) | T16: =IF(OR(M16="",N16=""),"",IF(M16+N16=0,"",N16/(M16+N16))) | U16: =IF(B16="","",COUNTIF('Past Flips'!$B$8:$B$307,B16)+COUNTIFS('Flip Candidates'!$B$8:$B$207,B16,'Flip Candidates'!$O$8:$O$207,"Likely flip")) | V16: =IF(OR(U16="",E16="",E16=0),"",U16/(E16*4)) | W16: =IF(B16="","",COUNTIF('Listing Watch'!$B$8:$B$307,B16)) | X16: =IF(B16="","",HYPERLINK("https://www.redfin.com/zipcode/"&B16&"/housing-market","Redfin")) | Y16: =IF(B16="","",HYPERLINK("https://data.census.gov/table/ACSDT5Y2024.B25032?g=860XX00US"&B16,"B25032")) | Z16: =IF(B16="","",HYPERLINK("https://censusreporter.org/profiles/86000US"&B16&"-"&B16&"/","Profile"))
R17: =IF(OR(E17="",F17="",E17=0),"",F17/(E17/3)) | S17: =IF(OR(D17="",K17="",D17=0),"",K17*12/D17) | T17: =IF(OR(M17="",N17=""),"",IF(M17+N17=0,"",N17/(M17+N17))) | U17: =IF(B17="","",COUNTIF('Past Flips'!$B$8:$B$307,B17)+COUNTIFS('Flip Candidates'!$B$8:$B$207,B17,'Flip Candidates'!$O$8:$O$207,"Likely flip")) | V17: =IF(OR(U17="",E17="",E17=0),"",U17/(E17*4)) | W17: =IF(B17="","",COUNTIF('Listing Watch'!$B$8:$B$307,B17)) | X17: =IF(B17="","",HYPERLINK("https://www.redfin.com/zipcode/"&B17&"/housing-market","Redfin")) | Y17: =IF(B17="","",HYPERLINK("https://data.census.gov/table/ACSDT5Y2024.B25032?g=860XX00US"&B17,"B25032")) | Z17: =IF(B17="","",HYPERLINK("https://censusreporter.org/profiles/86000US"&B17&"-"&B17&"/","Profile"))
R18: =IF(OR(E18="",F18="",E18=0),"",F18/(E18/3)) | S18: =IF(OR(D18="",K18="",D18=0),"",K18*12/D18) | T18: =IF(OR(M18="",N18=""),"",IF(M18+N18=0,"",N18/(M18+N18))) | U18: =IF(B18="","",COUNTIF('Past Flips'!$B$8:$B$307,B18)+COUNTIFS('Flip Candidates'!$B$8:$B$207,B18,'Flip Candidates'!$O$8:$O$207,"Likely flip")) | V18: =IF(OR(U18="",E18="",E18=0),"",U18/(E18*4)) | W18: =IF(B18="","",COUNTIF('Listing Watch'!$B$8:$B$307,B18)) | X18: =IF(B18="","",HYPERLINK("https://www.redfin.com/zipcode/"&B18&"/housing-market","Redfin")) | Y18: =IF(B18="","",HYPERLINK("https://data.census.gov/table/ACSDT5Y2024.B25032?g=860XX00US"&B18,"B25032")) | Z18: =IF(B18="","",HYPERLINK("https://censusreporter.org/profiles/86000US"&B18&"-"&B18&"/","Profile"))
R19: =IF(OR(E19="",F19="",E19=0),"",F19/(E19/3)) | S19: =IF(OR(D19="",K19="",D19=0),"",K19*12/D19) | T19: =IF(OR(M19="",N19=""),"",IF(M19+N19=0,"",N19/(M19+N19))) | U19: =IF(B19="","",COUNTIF('Past Flips'!$B$8:$B$307,B19)+COUNTIFS('Flip Candidates'!$B$8:$B$207,B19,'Flip Candidates'!$O$8:$O$207,"Likely flip")) | V19: =IF(OR(U19="",E19="",E19=0),"",U19/(E19*4)) | W19: =IF(B19="","",COUNTIF('Listing Watch'!$B$8:$B$307,B19)) | X19: =IF(B19="","",HYPERLINK("https://www.redfin.com/zipcode/"&B19&"/housing-market","Redfin")) | Y19: =IF(B19="","",HYPERLINK("https://data.census.gov/table/ACSDT5Y2024.B25032?g=860XX00US"&B19,"B25032")) | Z19: =IF(B19="","",HYPERLINK("https://censusreporter.org/profiles/86000US"&B19&"-"&B19&"/","Profile"))
R20: =IF(OR(E20="",F20="",E20=0),"",F20/(E20/3)) | S20: =IF(OR(D20="",K20="",D20=0),"",K20*12/D20) | T20: =IF(OR(M20="",N20=""),"",IF(M20+N20=0,"",N20/(M20+N20))) | U20: =IF(B20="","",COUNTIF('Past Flips'!$B$8:$B$307,B20)+COUNTIFS('Flip Candidates'!$B$8:$B$207,B20,'Flip Candidates'!$O$8:$O$207,"Likely flip")) | V20: =IF(OR(U20="",E20="",E20=0),"",U20/(E20*4)) | W20: =IF(B20="","",COUNTIF('Listing Watch'!$B$8:$B$307,B20)) | X20: =IF(B20="","",HYPERLINK("https://www.redfin.com/zipcode/"&B20&"/housing-market","Redfin")) | Y20: =IF(B20="","",HYPERLINK("https://data.census.gov/table/ACSDT5Y2024.B25032?g=860XX00US"&B20,"B25032")) | Z20: =IF(B20="","",HYPERLINK("https://censusreporter.org/profiles/86000US"&B20&"-"&B20&"/","Profile"))
... R107: =IF(OR(E107="",F107="",E107=0),"",F107/(E107/3)) | S107: =IF(OR(D107="",K107="",D107=0),"",K107*12/D107) | T107: =IF(OR(M107="",N107=""),"",IF(M107+N107=0,"",N107/(M107+N107))) | U107: =IF(B107="","",COUNTIF('Past Flips'!$B$8:$B$307,B107)+COUNTIFS('Flip Candidates'!$B$8:$B$207,B107,'Flip Candidates'!$O$8:$O$207,"Likely flip")) | V107: =IF(OR(U107="",E107="",E107=0),"",U107/(E107*4)) | W107: =IF(B107="","",COUNTIF('Listing Watch'!$B$8:$B$307,B107)) | X107: =IF(B107="","",HYPERLINK("https://www.redfin.com/zipcode/"&B107&"/housing-market","Redfin")) | Y107: =IF(B107="","",HYPERLINK("https://data.census.gov/table/ACSDT5Y2024.B25032?g=860XX00US"&B107,"B25032")) | Z107: =IF(B107="","",HYPERLINK("https://censusreporter.org/profiles/86000US"&B107&"-"&B107&"/","Profile"))

Sheet Listing Watch
A1: Listing Watch
A2: Save 20–30 listings per metro in your price range. Once a week, update Current price, Status and dates. This shows how fast deals really go.
A6: The house | I6: Track it weekly | R6: Calculated
A7: Metro | B7: ZIP | C7: Address | D7: Link | E7: Beds | F7: Baths | G7: Sqft | H7: Condition | I7: Listed on | J7: List price ($) | K7: Current price ($) | L7: Status | M7: Went pending on | N7: Sold on | O7: Sold price ($) | P7: Last checked | Q7: Notes | R7: Price cut | S7: Days to pending | T7: Sold vs. first list price | U7: List $/sqft | V7: Sold $/sqft
A8: Sampleville, OH | B8: EX001 | C8: 123 Example St | E8: 3 | F8: 1 | G8: 1150 | H8: Fixer | I8: 46266 | J8: 149900 | K8: 139900 | L8: Pending | M8: 46297 | P8: 46310 | Q8: EXAMPLE row: delete me | R8: =IF(OR(J8="",K8="",J8=0),"",1-K8/J8) -> 0.066711141 | S8: =IF(OR(I8="",M8=""),"",M8-I8) -> 31 | T8: =IF(OR(J8="",O8="",J8=0),"",O8/J8) | U8: =IF(OR(J8="",G8="",G8=0),"",J8/G8) -> 130.34783 | V8: =IF(OR(O8="",G8="",G8=0),"",O8/G8)
R9: =IF(OR(J9="",K9="",J9=0),"",1-K9/J9) | S9: =IF(OR(I9="",M9=""),"",M9-I9) | T9: =IF(OR(J9="",O9="",J9=0),"",O9/J9) | U9: =IF(OR(J9="",G9="",G9=0),"",J9/G9) | V9: =IF(OR(O9="",G9="",G9=0),"",O9/G9)
R10: =IF(OR(J10="",K10="",J10=0),"",1-K10/J10) | S10: =IF(OR(I10="",M10=""),"",M10-I10) | T10: =IF(OR(J10="",O10="",J10=0),"",O10/J10) | U10: =IF(OR(J10="",G10="",G10=0),"",J10/G10) | V10: =IF(OR(O10="",G10="",G10=0),"",O10/G10)
R11: =IF(OR(J11="",K11="",J11=0),"",1-K11/J11) | S11: =IF(OR(I11="",M11=""),"",M11-I11) | T11: =IF(OR(J11="",O11="",J11=0),"",O11/J11) | U11: =IF(OR(J11="",G11="",G11=0),"",J11/G11) | V11: =IF(OR(O11="",G11="",G11=0),"",O11/G11)
R12: =IF(OR(J12="",K12="",J12=0),"",1-K12/J12) | S12: =IF(OR(I12="",M12=""),"",M12-I12) | T12: =IF(OR(J12="",O12="",J12=0),"",O12/J12) | U12: =IF(OR(J12="",G12="",G12=0),"",J12/G12) | V12: =IF(OR(O12="",G12="",G12=0),"",O12/G12)
R13: =IF(OR(J13="",K13="",J13=0),"",1-K13/J13) | S13: =IF(OR(I13="",M13=""),"",M13-I13) | T13: =IF(OR(J13="",O13="",J13=0),"",O13/J13) | U13: =IF(OR(J13="",G13="",G13=0),"",J13/G13) | V13: =IF(OR(O13="",G13="",G13=0),"",O13/G13)
R14: =IF(OR(J14="",K14="",J14=0),"",1-K14/J14) | S14: =IF(OR(I14="",M14=""),"",M14-I14) | T14: =IF(OR(J14="",O14="",J14=0),"",O14/J14) | U14: =IF(OR(J14="",G14="",G14=0),"",J14/G14) | V14: =IF(OR(O14="",G14="",G14=0),"",O14/G14)
R15: =IF(OR(J15="",K15="",J15=0),"",1-K15/J15) | S15: =IF(OR(I15="",M15=""),"",M15-I15) | T15: =IF(OR(J15="",O15="",J15=0),"",O15/J15) | U15: =IF(OR(J15="",G15="",G15=0),"",J15/G15) | V15: =IF(OR(O15="",G15="",G15=0),"",O15/G15)
R16: =IF(OR(J16="",K16="",J16=0),"",1-K16/J16) | S16: =IF(OR(I16="",M16=""),"",M16-I16) | T16: =IF(OR(J16="",O16="",J16=0),"",O16/J16) | U16: =IF(OR(J16="",G16="",G16=0),"",J16/G16) | V16: =IF(OR(O16="",G16="",G16=0),"",O16/G16)
R17: =IF(OR(J17="",K17="",J17=0),"",1-K17/J17) | S17: =IF(OR(I17="",M17=""),"",M17-I17) | T17: =IF(OR(J17="",O17="",J17=0),"",O17/J17) | U17: =IF(OR(J17="",G17="",G17=0),"",J17/G17) | V17: =IF(OR(O17="",G17="",G17=0),"",O17/G17)
R18: =IF(OR(J18="",K18="",J18=0),"",1-K18/J18) | S18: =IF(OR(I18="",M18=""),"",M18-I18) | T18: =IF(OR(J18="",O18="",J18=0),"",O18/J18) | U18: =IF(OR(J18="",G18="",G18=0),"",J18/G18) | V18: =IF(OR(O18="",G18="",G18=0),"",O18/G18)
R19: =IF(OR(J19="",K19="",J19=0),"",1-K19/J19) | S19: =IF(OR(I19="",M19=""),"",M19-I19) | T19: =IF(OR(J19="",O19="",J19=0),"",O19/J19) | U19: =IF(OR(J19="",G19="",G19=0),"",J19/G19) | V19: =IF(OR(O19="",G19="",G19=0),"",O19/G19)
R20: =IF(OR(J20="",K20="",J20=0),"",1-K20/J20) | S20: =IF(OR(I20="",M20=""),"",M20-I20) | T20: =IF(OR(J20="",O20="",J20=0),"",O20/J20) | U20: =IF(OR(J20="",G20="",G20=0),"",J20/G20) | V20: =IF(OR(O20="",G20="",G20=0),"",O20/G20)
... R307: =IF(OR(J307="",K307="",J307=0),"",1-K307/J307) | S307: =IF(OR(I307="",M307=""),"",M307-I307) | T307: =IF(OR(J307="",O307="",J307=0),"",O307/J307) | U307: =IF(OR(J307="",G307="",G307=0),"",J307/G307) | V307: =IF(OR(O307="",G307="",G307=0),"",O307/G307)

Sheet Flip Candidates
A1: Flip Candidates
A2: Likely renovated resales: older houses that sold well above their ZIP's typical $/sqft. Open each link, look at the sale history, and type the EARLIER sale (yellow).
A6: From the Redfin "sold" download (OfferDesk fills these) | J6: You check the sale history | M6: Calculated
A7: Metro | B7: ZIP | C7: Address | D7: Link | E7: Sqft | F7: Year built | G7: Sold on | H7: Sold for ($) | I7: ZIP typical $/sqft | J7: Earlier sale date (from history) | K7: Earlier sale price ($) | L7: Notes | M7: Sold $/sqft | N7: Above ZIP $/sqft | O7: Flip? | P7: Months between sales | Q7: Est. profit ($) | R7: Profit % of resale
A8: Sampleville, OH | B8: EX001 | C8: 22 Flip St | E8: 1250 | F8: 1952 | G8: 46264 | H8: 209000 | I8: 142 | J8: 45996 | K8: 112000 | L8: EXAMPLE row: delete me | M8: =IF(OR(H8="",E8="",E8=0),"",H8/E8) -> 167.2 | N8: =IF(OR(M8="",I8="",I8=0),"",M8/I8-1) -> 0.17746479 | O8: =IF(OR(J8="",K8="",G8="",K8=0),"",IF(AND(G8-J8<=550,H8/K8-1>=0.25),"Likely flip","Not a flip")) -> Likely flip | P8: =IF(OR(J8="",G8=""),"",(G8-J8)/30.44) -> 8.804205 | Q8: =IF(O8<>"Likely flip","",H8-K8-E8*'Past Flips'!$E$3-H8*'Past Flips'!$E$4) -> 38600 | R8: =IF(OR(Q8="",H8=0),"",Q8/H8) -> 0.184689
M9: =IF(OR(H9="",E9="",E9=0),"",H9/E9) | N9: =IF(OR(M9="",I9="",I9=0),"",M9/I9-1) | O9: =IF(OR(J9="",K9="",G9="",K9=0),"",IF(AND(G9-J9<=550,H9/K9-1>=0.25),"Likely flip","Not a flip")) | P9: =IF(OR(J9="",G9=""),"",(G9-J9)/30.44) | Q9: =IF(O9<>"Likely flip","",H9-K9-E9*'Past Flips'!$E$3-H9*'Past Flips'!$E$4) | R9: =IF(OR(Q9="",H9=0),"",Q9/H9)
M10: =IF(OR(H10="",E10="",E10=0),"",H10/E10) | N10: =IF(OR(M10="",I10="",I10=0),"",M10/I10-1) | O10: =IF(OR(J10="",K10="",G10="",K10=0),"",IF(AND(G10-J10<=550,H10/K10-1>=0.25),"Likely flip","Not a flip")) | P10: =IF(OR(J10="",G10=""),"",(G10-J10)/30.44) | Q10: =IF(O10<>"Likely flip","",H10-K10-E10*'Past Flips'!$E$3-H10*'Past Flips'!$E$4) | R10: =IF(OR(Q10="",H10=0),"",Q10/H10)
M11: =IF(OR(H11="",E11="",E11=0),"",H11/E11) | N11: =IF(OR(M11="",I11="",I11=0),"",M11/I11-1) | O11: =IF(OR(J11="",K11="",G11="",K11=0),"",IF(AND(G11-J11<=550,H11/K11-1>=0.25),"Likely flip","Not a flip")) | P11: =IF(OR(J11="",G11=""),"",(G11-J11)/30.44) | Q11: =IF(O11<>"Likely flip","",H11-K11-E11*'Past Flips'!$E$3-H11*'Past Flips'!$E$4) | R11: =IF(OR(Q11="",H11=0),"",Q11/H11)
M12: =IF(OR(H12="",E12="",E12=0),"",H12/E12) | N12: =IF(OR(M12="",I12="",I12=0),"",M12/I12-1) | O12: =IF(OR(J12="",K12="",G12="",K12=0),"",IF(AND(G12-J12<=550,H12/K12-1>=0.25),"Likely flip","Not a flip")) | P12: =IF(OR(J12="",G12=""),"",(G12-J12)/30.44) | Q12: =IF(O12<>"Likely flip","",H12-K12-E12*'Past Flips'!$E$3-H12*'Past Flips'!$E$4) | R12: =IF(OR(Q12="",H12=0),"",Q12/H12)
M13: =IF(OR(H13="",E13="",E13=0),"",H13/E13) | N13: =IF(OR(M13="",I13="",I13=0),"",M13/I13-1) | O13: =IF(OR(J13="",K13="",G13="",K13=0),"",IF(AND(G13-J13<=550,H13/K13-1>=0.25),"Likely flip","Not a flip")) | P13: =IF(OR(J13="",G13=""),"",(G13-J13)/30.44) | Q13: =IF(O13<>"Likely flip","",H13-K13-E13*'Past Flips'!$E$3-H13*'Past Flips'!$E$4) | R13: =IF(OR(Q13="",H13=0),"",Q13/H13)
M14: =IF(OR(H14="",E14="",E14=0),"",H14/E14) | N14: =IF(OR(M14="",I14="",I14=0),"",M14/I14-1) | O14: =IF(OR(J14="",K14="",G14="",K14=0),"",IF(AND(G14-J14<=550,H14/K14-1>=0.25),"Likely flip","Not a flip")) | P14: =IF(OR(J14="",G14=""),"",(G14-J14)/30.44) | Q14: =IF(O14<>"Likely flip","",H14-K14-E14*'Past Flips'!$E$3-H14*'Past Flips'!$E$4) | R14: =IF(OR(Q14="",H14=0),"",Q14/H14)
M15: =IF(OR(H15="",E15="",E15=0),"",H15/E15) | N15: =IF(OR(M15="",I15="",I15=0),"",M15/I15-1) | O15: =IF(OR(J15="",K15="",G15="",K15=0),"",IF(AND(G15-J15<=550,H15/K15-1>=0.25),"Likely flip","Not a flip")) | P15: =IF(OR(J15="",G15=""),"",(G15-J15)/30.44) | Q15: =IF(O15<>"Likely flip","",H15-K15-E15*'Past Flips'!$E$3-H15*'Past Flips'!$E$4) | R15: =IF(OR(Q15="",H15=0),"",Q15/H15)
M16: =IF(OR(H16="",E16="",E16=0),"",H16/E16) | N16: =IF(OR(M16="",I16="",I16=0),"",M16/I16-1) | O16: =IF(OR(J16="",K16="",G16="",K16=0),"",IF(AND(G16-J16<=550,H16/K16-1>=0.25),"Likely flip","Not a flip")) | P16: =IF(OR(J16="",G16=""),"",(G16-J16)/30.44) | Q16: =IF(O16<>"Likely flip","",H16-K16-E16*'Past Flips'!$E$3-H16*'Past Flips'!$E$4) | R16: =IF(OR(Q16="",H16=0),"",Q16/H16)
M17: =IF(OR(H17="",E17="",E17=0),"",H17/E17) | N17: =IF(OR(M17="",I17="",I17=0),"",M17/I17-1) | O17: =IF(OR(J17="",K17="",G17="",K17=0),"",IF(AND(G17-J17<=550,H17/K17-1>=0.25),"Likely flip","Not a flip")) | P17: =IF(OR(J17="",G17=""),"",(G17-J17)/30.44) | Q17: =IF(O17<>"Likely flip","",H17-K17-E17*'Past Flips'!$E$3-H17*'Past Flips'!$E$4) | R17: =IF(OR(Q17="",H17=0),"",Q17/H17)
M18: =IF(OR(H18="",E18="",E18=0),"",H18/E18) | N18: =IF(OR(M18="",I18="",I18=0),"",M18/I18-1) | O18: =IF(OR(J18="",K18="",G18="",K18=0),"",IF(AND(G18-J18<=550,H18/K18-1>=0.25),"Likely flip","Not a flip")) | P18: =IF(OR(J18="",G18=""),"",(G18-J18)/30.44) | Q18: =IF(O18<>"Likely flip","",H18-K18-E18*'Past Flips'!$E$3-H18*'Past Flips'!$E$4) | R18: =IF(OR(Q18="",H18=0),"",Q18/H18)
M19: =IF(OR(H19="",E19="",E19=0),"",H19/E19) | N19: =IF(OR(M19="",I19="",I19=0),"",M19/I19-1) | O19: =IF(OR(J19="",K19="",G19="",K19=0),"",IF(AND(G19-J19<=550,H19/K19-1>=0.25),"Likely flip","Not a flip")) | P19: =IF(OR(J19="",G19=""),"",(G19-J19)/30.44) | Q19: =IF(O19<>"Likely flip","",H19-K19-E19*'Past Flips'!$E$3-H19*'Past Flips'!$E$4) | R19: =IF(OR(Q19="",H19=0),"",Q19/H19)
M20: =IF(OR(H20="",E20="",E20=0),"",H20/E20) | N20: =IF(OR(M20="",I20="",I20=0),"",M20/I20-1) | O20: =IF(OR(J20="",K20="",G20="",K20=0),"",IF(AND(G20-J20<=550,H20/K20-1>=0.25),"Likely flip","Not a flip")) | P20: =IF(OR(J20="",G20=""),"",(G20-J20)/30.44) | Q20: =IF(O20<>"Likely flip","",H20-K20-E20*'Past Flips'!$E$3-H20*'Past Flips'!$E$4) | R20: =IF(OR(Q20="",H20=0),"",Q20/H20)
... M207: =IF(OR(H207="",E207="",E207=0),"",H207/E207) | N207: =IF(OR(M207="",I207="",I207=0),"",M207/I207-1) | O207: =IF(OR(J207="",K207="",G207="",K207=0),"",IF(AND(G207-J207<=550,H207/K207-1>=0.25),"Likely flip","Not a flip")) | P207: =IF(OR(J207="",G207=""),"",(G207-J207)/30.44) | Q207: =IF(O207<>"Likely flip","",H207-K207-E207*'Past Flips'!$E$3-H207*'Past Flips'!$E$4) | R207: =IF(OR(Q207="",H207=0),"",Q207/H207)

Sheet Past Flips
A1: Past Flips
A2: Houses that sold, then resold for a lot more within ~12 months. They prove flips work here, show the profit, and show how many flippers are active.
A3: Rehab $/sqft to assume when you don't know it | E3: 30 | F3: Your assumption. Replace it with what local contractors tell you (Calls tab).
A4: Buy + sell + holding costs, as % of the resale price | E4: 0.1 | F4: Your assumption: agent fees, closing costs, taxes, insurance, utilities while holding. 10% is a common rough figure.
A6: The house | E6: The two sales | M6: Calculated (rough: you don't know their real rehab)
A7: Metro | B7: ZIP | C7: Address | D7: Sqft | E7: Bought on | F7: Bought for ($) | G7: Sold on | H7: Sold for ($) | I7: Rehab ($) if known | J7: Flipper (name or LLC) | K7: Where you found it | L7: Notes | M7: Months held | N7: Price jump ($) | O7: Bought $/sqft | P7: Sold $/sqft | Q7: Rehab used ($) | R7: Other costs ($) | S7: Est. profit ($) | T7: Profit % of resale
A8: Sampleville, OH | B8: EX001 | C8: 456 Sample Ave | D8: 1300 | E8: 45971 | F8: 118000 | G8: 46162 | H8: 214900 | J8: ABC Homes LLC | K8: Zillow sale history | L8: EXAMPLE row: delete me | M8: =IF(OR(E8="",G8=""),"",(G8-E8)/30.44) -> 6.2746386 | N8: =IF(OR(F8="",H8=""),"",H8-F8) -> 96900 | O8: =IF(OR(F8="",D8="",D8=0),"",F8/D8) -> 90.769231 | P8: =IF(OR(H8="",D8="",D8=0),"",H8/D8) -> 165.30769 | Q8: =IF(H8="","",IF(I8<>"",I8,IF(D8="","",D8*$E$3))) -> 39000 | R8: =IF(H8="","",H8*$E$4) -> 21490 | S8: =IF(OR(F8="",H8="",Q8=""),"",H8-F8-Q8-R8) -> 36410 | T8: =IF(OR(S8="",H8="",H8=0),"",S8/H8) -> 0.16942764
M9: =IF(OR(E9="",G9=""),"",(G9-E9)/30.44) | N9: =IF(OR(F9="",H9=""),"",H9-F9) | O9: =IF(OR(F9="",D9="",D9=0),"",F9/D9) | P9: =IF(OR(H9="",D9="",D9=0),"",H9/D9) | Q9: =IF(H9="","",IF(I9<>"",I9,IF(D9="","",D9*$E$3))) | R9: =IF(H9="","",H9*$E$4) | S9: =IF(OR(F9="",H9="",Q9=""),"",H9-F9-Q9-R9) | T9: =IF(OR(S9="",H9="",H9=0),"",S9/H9)
M10: =IF(OR(E10="",G10=""),"",(G10-E10)/30.44) | N10: =IF(OR(F10="",H10=""),"",H10-F10) | O10: =IF(OR(F10="",D10="",D10=0),"",F10/D10) | P10: =IF(OR(H10="",D10="",D10=0),"",H10/D10) | Q10: =IF(H10="","",IF(I10<>"",I10,IF(D10="","",D10*$E$3))) | R10: =IF(H10="","",H10*$E$4) | S10: =IF(OR(F10="",H10="",Q10=""),"",H10-F10-Q10-R10) | T10: =IF(OR(S10="",H10="",H10=0),"",S10/H10)
M11: =IF(OR(E11="",G11=""),"",(G11-E11)/30.44) | N11: =IF(OR(F11="",H11=""),"",H11-F11) | O11: =IF(OR(F11="",D11="",D11=0),"",F11/D11) | P11: =IF(OR(H11="",D11="",D11=0),"",H11/D11) | Q11: =IF(H11="","",IF(I11<>"",I11,IF(D11="","",D11*$E$3))) | R11: =IF(H11="","",H11*$E$4) | S11: =IF(OR(F11="",H11="",Q11=""),"",H11-F11-Q11-R11) | T11: =IF(OR(S11="",H11="",H11=0),"",S11/H11)
M12: =IF(OR(E12="",G12=""),"",(G12-E12)/30.44) | N12: =IF(OR(F12="",H12=""),"",H12-F12) | O12: =IF(OR(F12="",D12="",D12=0),"",F12/D12) | P12: =IF(OR(H12="",D12="",D12=0),"",H12/D12) | Q12: =IF(H12="","",IF(I12<>"",I12,IF(D12="","",D12*$E$3))) | R12: =IF(H12="","",H12*$E$4) | S12: =IF(OR(F12="",H12="",Q12=""),"",H12-F12-Q12-R12) | T12: =IF(OR(S12="",H12="",H12=0),"",S12/H12)
M13: =IF(OR(E13="",G13=""),"",(G13-E13)/30.44) | N13: =IF(OR(F13="",H13=""),"",H13-F13) | O13: =IF(OR(F13="",D13="",D13=0),"",F13/D13) | P13: =IF(OR(H13="",D13="",D13=0),"",H13/D13) | Q13: =IF(H13="","",IF(I13<>"",I13,IF(D13="","",D13*$E$3))) | R13: =IF(H13="","",H13*$E$4) | S13: =IF(OR(F13="",H13="",Q13=""),"",H13-F13-Q13-R13) | T13: =IF(OR(S13="",H13="",H13=0),"",S13/H13)
M14: =IF(OR(E14="",G14=""),"",(G14-E14)/30.44) | N14: =IF(OR(F14="",H14=""),"",H14-F14) | O14: =IF(OR(F14="",D14="",D14=0),"",F14/D14) | P14: =IF(OR(H14="",D14="",D14=0),"",H14/D14) | Q14: =IF(H14="","",IF(I14<>"",I14,IF(D14="","",D14*$E$3))) | R14: =IF(H14="","",H14*$E$4) | S14: =IF(OR(F14="",H14="",Q14=""),"",H14-F14-Q14-R14) | T14: =IF(OR(S14="",H14="",H14=0),"",S14/H14)
M15: =IF(OR(E15="",G15=""),"",(G15-E15)/30.44) | N15: =IF(OR(F15="",H15=""),"",H15-F15) | O15: =IF(OR(F15="",D15="",D15=0),"",F15/D15) | P15: =IF(OR(H15="",D15="",D15=0),"",H15/D15) | Q15: =IF(H15="","",IF(I15<>"",I15,IF(D15="","",D15*$E$3))) | R15: =IF(H15="","",H15*$E$4) | S15: =IF(OR(F15="",H15="",Q15=""),"",H15-F15-Q15-R15) | T15: =IF(OR(S15="",H15="",H15=0),"",S15/H15)
M16: =IF(OR(E16="",G16=""),"",(G16-E16)/30.44) | N16: =IF(OR(F16="",H16=""),"",H16-F16) | O16: =IF(OR(F16="",D16="",D16=0),"",F16/D16) | P16: =IF(OR(H16="",D16="",D16=0),"",H16/D16) | Q16: =IF(H16="","",IF(I16<>"",I16,IF(D16="","",D16*$E$3))) | R16: =IF(H16="","",H16*$E$4) | S16: =IF(OR(F16="",H16="",Q16=""),"",H16-F16-Q16-R16) | T16: =IF(OR(S16="",H16="",H16=0),"",S16/H16)
M17: =IF(OR(E17="",G17=""),"",(G17-E17)/30.44) | N17: =IF(OR(F17="",H17=""),"",H17-F17) | O17: =IF(OR(F17="",D17="",D17=0),"",F17/D17) | P17: =IF(OR(H17="",D17="",D17=0),"",H17/D17) | Q17: =IF(H17="","",IF(I17<>"",I17,IF(D17="","",D17*$E$3))) | R17: =IF(H17="","",H17*$E$4) | S17: =IF(OR(F17="",H17="",Q17=""),"",H17-F17-Q17-R17) | T17: =IF(OR(S17="",H17="",H17=0),"",S17/H17)
M18: =IF(OR(E18="",G18=""),"",(G18-E18)/30.44) | N18: =IF(OR(F18="",H18=""),"",H18-F18) | O18: =IF(OR(F18="",D18="",D18=0),"",F18/D18) | P18: =IF(OR(H18="",D18="",D18=0),"",H18/D18) | Q18: =IF(H18="","",IF(I18<>"",I18,IF(D18="","",D18*$E$3))) | R18: =IF(H18="","",H18*$E$4) | S18: =IF(OR(F18="",H18="",Q18=""),"",H18-F18-Q18-R18) | T18: =IF(OR(S18="",H18="",H18=0),"",S18/H18)
M19: =IF(OR(E19="",G19=""),"",(G19-E19)/30.44) | N19: =IF(OR(F19="",H19=""),"",H19-F19) | O19: =IF(OR(F19="",D19="",D19=0),"",F19/D19) | P19: =IF(OR(H19="",D19="",D19=0),"",H19/D19) | Q19: =IF(H19="","",IF(I19<>"",I19,IF(D19="","",D19*$E$3))) | R19: =IF(H19="","",H19*$E$4) | S19: =IF(OR(F19="",H19="",Q19=""),"",H19-F19-Q19-R19) | T19: =IF(OR(S19="",H19="",H19=0),"",S19/H19)
M20: =IF(OR(E20="",G20=""),"",(G20-E20)/30.44) | N20: =IF(OR(F20="",H20=""),"",H20-F20) | O20: =IF(OR(F20="",D20="",D20=0),"",F20/D20) | P20: =IF(OR(H20="",D20="",D20=0),"",H20/D20) | Q20: =IF(H20="","",IF(I20<>"",I20,IF(D20="","",D20*$E$3))) | R20: =IF(H20="","",H20*$E$4) | S20: =IF(OR(F20="",H20="",Q20=""),"",H20-F20-Q20-R20) | T20: =IF(OR(S20="",H20="",H20=0),"",S20/H20)
